2023-06-15 20:08:54,269 INFO    MainThread:592703 [internal.py:wandb_internal():87] W&B internal server running at pid: 592703, started at: 2023-06-15 20:08:54.269237
2023-06-15 20:08:54,270 DEBUG   HandlerThread:592703 [handler.py:handle_request():130] handle_request: check_version
2023-06-15 20:08:54,271 INFO    WriterThread:592703 [datastore.py:open_for_write():77] open: /home/ck/shivani_research/TD3-error-control/wandb/run-20230615_200853-36ty8wtg/run-36ty8wtg.wandb
2023-06-15 20:08:54,271 DEBUG   SenderThread:592703 [sender.py:send():234] send: header
2023-06-15 20:08:54,271 DEBUG   SenderThread:592703 [sender.py:send_request():248] send_request: check_version
2023-06-15 20:08:54,410 DEBUG   SenderThread:592703 [sender.py:send():234] send: run
2023-06-15 20:08:54,781 ERROR   SenderThread:592703 [internal_api.py:execute():144] 404 response executing GraphQL.
2023-06-15 20:08:54,781 ERROR   SenderThread:592703 [internal_api.py:execute():145] {"errors":[{"message":"project not found","path":["upsertBucket"]}],"data":{"upsertBucket":null}}
2023-06-15 20:08:55,411 INFO    WriterThread:592703 [datastore.py:close():281] close: /home/ck/shivani_research/TD3-error-control/wandb/run-20230615_200853-36ty8wtg/run-36ty8wtg.wandb
2023-06-15 20:08:55,411 INFO    HandlerThread:592703 [handler.py:finish():731] shutting down handler
2023-06-15 20:08:55,411 ERROR   MainThread:592703 [internal.py:wandb_internal():158] Thread SenderThread:
Traceback (most recent call last):
  File "/home/ck/miniconda3/envs/selfplay/lib/python3.8/site-packages/wandb/sdk/lib/retry.py", line 102, in __call__
    result = self._call_fn(*args, **kwargs)
  File "/home/ck/miniconda3/envs/selfplay/lib/python3.8/site-packages/wandb/sdk/internal/internal_api.py", line 147, in execute
    six.reraise(*sys.exc_info())
  File "/home/ck/miniconda3/envs/selfplay/lib/python3.8/site-packages/six.py", line 719, in reraise
    raise value
  File "/home/ck/miniconda3/envs/selfplay/lib/python3.8/site-packages/wandb/sdk/internal/internal_api.py", line 141, in execute
    return self.client.execute(*args, **kwargs)
  File "/home/ck/miniconda3/envs/selfplay/lib/python3.8/site-packages/wandb/vendor/gql-0.2.0/gql/client.py", line 52, in execute
    result = self._get_result(document, *args, **kwargs)
  File "/home/ck/miniconda3/envs/selfplay/lib/python3.8/site-packages/wandb/vendor/gql-0.2.0/gql/client.py", line 60, in _get_result
    return self.transport.execute(document, *args, **kwargs)
  File "/home/ck/miniconda3/envs/selfplay/lib/python3.8/site-packages/wandb/vendor/gql-0.2.0/gql/transport/requests.py", line 39, in execute
    request.raise_for_status()
  File "/home/ck/miniconda3/envs/selfplay/lib/python3.8/site-packages/requests/models.py", line 941, in raise_for_status
    raise HTTPError(http_error_msg, response=self)
requests.exceptions.HTTPError: 404 Client Error: Not Found for url: https://api.wandb.ai/graphql

During handling of the above exception, another exception occurred:

Traceback (most recent call last):
  File "/home/ck/miniconda3/envs/selfplay/lib/python3.8/site-packages/wandb/apis/normalize.py", line 24, in wrapper
    return func(*args, **kwargs)
  File "/home/ck/miniconda3/envs/selfplay/lib/python3.8/site-packages/wandb/sdk/internal/internal_api.py", line 1298, in upsert_run
    response = self.gql(mutation, variable_values=variable_values, **kwargs)
  File "/home/ck/miniconda3/envs/selfplay/lib/python3.8/site-packages/wandb/sdk/lib/retry.py", line 118, in __call__
    if not check_retry_fn(e):
  File "/home/ck/miniconda3/envs/selfplay/lib/python3.8/site-packages/wandb/util.py", line 821, in no_retry_auth
    raise CommError("Permission denied, ask the project owner to grant you access")
wandb.errors.CommError: Permission denied, ask the project owner to grant you access

During handling of the above exception, another exception occurred:

Traceback (most recent call last):
  File "/home/ck/miniconda3/envs/selfplay/lib/python3.8/site-packages/wandb/sdk/internal/internal_util.py", line 52, in run
    self._run()
  File "/home/ck/miniconda3/envs/selfplay/lib/python3.8/site-packages/wandb/sdk/internal/internal_util.py", line 102, in _run
    self._process(record)
  File "/home/ck/miniconda3/envs/selfplay/lib/python3.8/site-packages/wandb/sdk/internal/internal.py", line 291, in _process
    self._sm.send(record)
  File "/home/ck/miniconda3/envs/selfplay/lib/python3.8/site-packages/wandb/sdk/internal/sender.py", line 236, in send
    send_handler(record)
  File "/home/ck/miniconda3/envs/selfplay/lib/python3.8/site-packages/wandb/sdk/internal/sender.py", line 687, in send_run
    self._init_run(run, config_value_dict)
  File "/home/ck/miniconda3/envs/selfplay/lib/python3.8/site-packages/wandb/sdk/internal/sender.py", line 711, in _init_run
    server_run, inserted = self._api.upsert_run(
  File "/home/ck/miniconda3/envs/selfplay/lib/python3.8/site-packages/wandb/apis/normalize.py", line 62, in wrapper
    six.reraise(CommError, CommError(message, err), sys.exc_info()[2])
  File "/home/ck/miniconda3/envs/selfplay/lib/python3.8/site-packages/six.py", line 718, in reraise
    raise value.with_traceback(tb)
  File "/home/ck/miniconda3/envs/selfplay/lib/python3.8/site-packages/wandb/apis/normalize.py", line 24, in wrapper
    return func(*args, **kwargs)
  File "/home/ck/miniconda3/envs/selfplay/lib/python3.8/site-packages/wandb/sdk/internal/internal_api.py", line 1298, in upsert_run
    response = self.gql(mutation, variable_values=variable_values, **kwargs)
  File "/home/ck/miniconda3/envs/selfplay/lib/python3.8/site-packages/wandb/sdk/lib/retry.py", line 118, in __call__
    if not check_retry_fn(e):
  File "/home/ck/miniconda3/envs/selfplay/lib/python3.8/site-packages/wandb/util.py", line 821, in no_retry_auth
    raise CommError("Permission denied, ask the project owner to grant you access")
wandb.errors.CommError: Permission denied, ask the project owner to grant you access
2023-06-15 20:08:57,422 INFO    MainThread:592703 [internal.py:handle_exit():77] Internal process exited
